Started by user [8mha:////4K/OHdAn9vapfRhDztv+0ir95MIxdVgKrfxDBxgE6I7FAAAAlx+LCAAAAAAAAP9b85aBtbiIQTGjNKU4P08vOT+vOD8nVc83PyU1x6OyILUoJzMv2y+/JJUBAhiZGBgqihhk0NSjKDWzXb3RdlLBUSYGJk8GtpzUvPSSDB8G5tKinBIGIZ+sxLJE/ZzEvHT94JKizLx0a6BxUmjGOUNodHsLgAzWEgZu/dLi1CL9xJTczDwAj6GcLcAAAAA=[0madmin
Running as SYSTEM
Building in workspace /var/jenkins_home/jobs/rest_api/workspace
[workspace] $ /bin/sh -xe /tmp/jenkins1849113504662004426.sh
+ pytest /code --alluredir /var/jenkins_home/jobs/rest_api/workspace/allure-results
============================= test session starts ==============================
platform linux -- Python 3.9.2, pytest-7.2.1, pluggy-1.0.0
rootdir: /code, configfile: pytest.ini
plugins: Faker-16.8.1, allure-pytest-2.12.0
collected 10 items

../../../../../code/test_API.py .........F                               [100%]

=================================== FAILURES ===================================
__________________ test_create_with_invalid_data[book_data2] ___________________

client = <api.api_client.ApiClient object at 0xffffa4fa9790>
book_data = ('asd', False, 2, 'asd')

    @pytest.mark.negative
    @pytest.mark.parametrize("book_data", [(2, 'asd'), (2, 2, 2, "asd"), ('asd', False, 2, "asd")])
    def test_create_with_invalid_data(client, book_data):
        """Проверяем, что нельзя создать книгу с некорректными данными, нарушиющих типы"""
        book_response = client.add_book(*book_data)
>       assert book_response.status_code == 400
E       assert 201 == 400
E        +  where 201 = ApiResponse(json={'book': {'author': False, 'id': 6, 'isElectronicBook': 2, 'name': 'asd', 'year': 'asd'}}, text='{"bo...alse,"id":6,"isElectronicBook":2,"name":"asd","year":"asd"}}\n', status_code=201, url='http://rest_api:5000/api/books').status_code

/code/test_API.py:96: AssertionError
=============================== warnings summary ===============================
../../../../../usr/local/lib/python3.9/dist-packages/_pytest/cacheprovider.py:433
  /usr/local/lib/python3.9/dist-packages/_pytest/cacheprovider.py:433: PytestCacheWarning: cache could not write path /code/.pytest_cache/v/cache/nodeids
    config.cache.set("cache/nodeids", sorted(self.cached_nodeids))

../../../../../usr/local/lib/python3.9/dist-packages/_pytest/cacheprovider.py:387
  /usr/local/lib/python3.9/dist-packages/_pytest/cacheprovider.py:387: PytestCacheWarning: cache could not write path /code/.pytest_cache/v/cache/lastfailed
    config.cache.set("cache/lastfailed", self.lastfailed)

../../../../../usr/local/lib/python3.9/dist-packages/_pytest/stepwise.py:56
  /usr/local/lib/python3.9/dist-packages/_pytest/stepwise.py:56: PytestCacheWarning: cache could not write path /code/.pytest_cache/v/cache/stepwise
    session.config.cache.set(STEPWISE_CACHE_DIR, [])

-- Docs: https://docs.pytest.org/en/stable/how-to/capture-warnings.html
=========================== short test summary info ============================
FAILED ../../../../../code/test_API.py::test_create_with_invalid_data[book_data2] - assert 201 == 400
 +  where 201 = ApiResponse(json={'book': {'author': False, 'id': 6, 'isElectronicBook': 2, 'name': 'asd', 'year': 'asd'}}, text='{"bo...alse,"id":6,"isElectronicBook":2,"name":"asd","year":"asd"}}\n', status_code=201, url='http://rest_api:5000/api/books').status_code
=================== 1 failed, 9 passed, 3 warnings in 0.53s ====================
Build step 'Execute shell' marked build as failure
[workspace] $ /var/jenkins_home/tools/ru.yandex.qatools.allure.jenkins.tools.AllureCommandlineInstallation/cal/bin/allure generate /var/jenkins_home/jobs/rest_api/workspace/ALLURE-RESULTS -c -o /var/jenkins_home/jobs/rest_api/workspace/allure-report
Report successfully generated to /var/jenkins_home/jobs/rest_api/workspace/allure-report
Allure report was successfully generated.
Creating artifact for the build.
Artifact was added to the build.
Finished: FAILURE
