{"uuid": "23a3ca13-0173-4948-8357-6360db1b7d05", "children": ["e2f50b3b-04e3-463c-80ae-39fd431e66cf"], "befores": [{"name": "temp_book", "status": "broken", "statusDetails": {"message": "requests.exceptions.ConnectionError: HTTPConnectionPool(host='127.0.0.1', port=5000): Max retries exceeded with url: /api/books (Caused by NewConnectionError('<urllib3.connection.HTTPConnection object at 0xffff7e625730>: Failed to establish a new connection: [Errno 111] Connection refused'))\n", "trace": "  File \"/usr/local/lib/python3.9/dist-packages/pluggy/_callers.py\", line 39, in _multicall\n    res = hook_impl.function(*args)\n  File \"/usr/local/lib/python3.9/dist-packages/_pytest/fixtures.py\", line 1129, in pytest_fixture_setup\n    result = call_fixture_func(fixturefunc, request, kwargs)\n  File \"/usr/local/lib/python3.9/dist-packages/_pytest/fixtures.py\", line 901, in call_fixture_func\n    fixture_result = next(generator)\n  File \"/code/conftest.py\", line 16, in temp_book\n    book_response = client.add_book(*utils.random_book())\n  File \"/code/api/api_client.py\", line 27, in add_book\n    response = self.request('post', 'api/books', json=data)\n  File \"/code/api/base_api.py\", line 20, in request\n    requests_response = self.session.request(method, self.base_url + url, **kwargs)\n  File \"/usr/local/lib/python3.9/dist-packages/requests/sessions.py\", line 587, in request\n    resp = self.send(prep, **send_kwargs)\n  File \"/usr/local/lib/python3.9/dist-packages/requests/sessions.py\", line 701, in send\n    r = adapter.send(request, **kwargs)\n  File \"/usr/local/lib/python3.9/dist-packages/requests/adapters.py\", line 565, in send\n    raise ConnectionError(e, request=request)\n"}, "start": 1676238308051, "stop": 1676238308054}], "start": 1676238308051, "stop": 1676238308116}